Workbook

Sheet Como usar
A1: Rota Comercial Z7 — planilha de prospecção
A2: Lavanderia de autosserviço do Posto Zandoná Z7 · R. Ottokar Doerffel, 1489 · Anita Garibaldi, Joinville/SC
A4: As abas
A5: Contatos — os 62 alvos já levantados, em ordem de distância do posto. A mensagem de cada um é montada sozinha.
A6: Anfitriões Airbnb — aba em branco para você preencher a partir dos anúncios que achar. Monta a mensagem sozinha também.
A7: Mensagens — os 11 roteiros, um por tipo de cliente. Editou aqui, muda em todas as linhas das outras abas.
A9: O que você preenche
A10: Só as células de fundo amarelo. Todo o resto é calculado.
A11: Na aba Contatos: Status e Observações.
A12: Na aba Anfitriões Airbnb: tudo até a coluna Onde achou o telefone.
A14: Sobre o telefone do anfitrião do Airbnb
A15: O Airbnb não publica telefone de anfitrião em lugar nenhum do anúncio, nem para quem está logado. O número só
... A27: Ela abre a conversa; a mensagem fica na coluna ao lado, para você copiar e colar.

Sheet Contatos
A1: Prioridade | B1: Segmento | C1: Nome | D1: Porte | E1: Endereço | F1: Bairro | G1: Distância do Z7 | H1: Telefone | I1: Telefone 2 | J1: Contato extra | K1: Roteiro | L1: Tel 1 (dígitos) | M1: Tel 2 (dígitos) | N1: Celular p/ WhatsApp | O1: Link WhatsApp | P1: Mensagem pronta | Q1: Status | R1: Observações
A2: 1 | B2: Barbearia/Salao | C2: Barbearia Joinville | E2: R. Rio Grande do Sul, 260 - sala 03 | F2: Anita Garibaldi | G2: ate 1 km | H2: (47) 99945-1884 | K2: beleza | L2: =SUBSTITUTE(SUBSTITUTE(SUBSTITUTE(SUBSTITUTE($H2,"(",""),")","")," ",""),"-","") -> 47999451884 | M2: =SUBSTITUTE(SUBSTITUTE(SUBSTITUTE(SUBSTITUTE($I2,"(",""),")","")," ",""),"-","") | N2: =IF(LEN($L2)=11,$L2,IF(LEN($M2)=11,$M2,"")) -> 47999451884 | O2: =IF($N2="","",HYPERLINK("https://wa.me/55"&$N2,"Abrir conversa")) -> Abrir conversa | P2: =SUBSTITUTE(INDEX(Mensagens!$D$2:$D$12,MATCH($K2,Mensagens!$A$2:$A$12,0)),"[nome]",$C2) -> Oi, tudo bem? Sou o Luis Carlos, da lavanderia do Posto Zandoná, aqui na Ottokar Doerffel. Autosserviço com máquina e secadora industrial. Pra salão o ponto é a secadora: toalha que seca no varal fica dura e com cheiro de úmido; na secadora volta macia no mesmo dia. É uma parada de uma hora por semana, e ninguém da equipe precisa levar sacola pra casa. Deixo a primeira lavagem por minha conta pra você comparar. Pode ser? | Q2: A contatar
A3: 1 | B3: Barbearia/Salao | C3: Barbearia Navajo | E3: R. Ottokar Doerffel, 730 - sala 4 | F3: Atiradores | G3: ate 1 km | K3: beleza | L3: =SUBSTITUTE(SUBSTITUTE(SUBSTITUTE(SUBSTITUTE($H3,"(",""),")","")," ",""),"-","") | M3: =SUBSTITUTE(SUBSTITUTE(SUBSTITUTE(SUBSTITUTE($I3,"(",""),")","")," ",""),"-","") | N3: =IF(LEN($L3)=11,$L3,IF(LEN($M3)=11,$M3,"")) | O3: =IF($N3="","",HYPERLINK("https://wa.me/55"&$N3,"Abrir conversa")) | P3: =SUBSTITUTE(INDEX(Mensagens!$D$2:$D$12,MATCH($K3,Mensagens!$A$2:$A$12,0)),"[nome]",$C3) -> Oi, tudo bem? Sou o Luis Carlos, da lavanderia do Posto Zandoná, aqui na Ottokar Doerffel. Autosserviço com máquina e secadora industrial. Pra salão o ponto é a secadora: toalha que seca no varal fica dura e com cheiro de úmido; na secadora volta macia no mesmo dia. É uma parada de uma hora por semana, e ninguém da equipe precisa levar sacola pra casa. Deixo a primeira lavagem por minha conta pra você comparar. Pode ser? | Q3: A contatar
A4: 1 | B4: Academia | C4: Complexo Esportivo Oda Fitness | E4: R. Parana, 56 | F4: Anita Garibaldi | G4: ate 1 km | H4: (47) 3429-2031 | K4: academia | L4: =SUBSTITUTE(SUBSTITUTE(SUBSTITUTE(SUBSTITUTE($H4,"(",""),")","")," ",""),"-","") -> 4734292031 | M4: =SUBSTITUTE(SUBSTITUTE(SUBSTITUTE(SUBSTITUTE($I4,"(",""),")","")," ",""),"-","") | N4: =IF(LEN($L4)=11,$L4,IF(LEN($M4)=11,$M4,"")) | O4: =IF($N4="","",HYPERLINK("https://wa.me/55"&$N4,"Abrir conversa")) | P4: =SUBSTITUTE(INDEX(Mensagens!$D$2:$D$12,MATCH($K4,Mensagens!$A$2:$A$12,0)),"[nome]",$C4) -> Oi! Sou o Luis Carlos, da lavanderia do Posto Zandoná, aqui na Ottokar Doerffel. Autosserviço com máquina e secadora industrial: toalha de treino e pano de higienização lavam e secam numa parada só — sem máquina rodando no intervalo e sem ninguém da recepção cuidando disso. Das 6h às 22h, com estacionamento na porta. Primeira lavagem por minha conta pra você ver o resultado. Quando fica bom testar? | Q4: A contatar
A5: 1 | B5: Multiplicador | C5: Construtora Convisa | E5: R. Jacob Eisenhuth, 572 | F5: Atiradores | G5: ate 1 km | H5: (47) 3032-4400 | J5: seg-sex 8h-18h, sab 8h-14h | K5: construtora | L5: =SUBSTITUTE(SUBSTITUTE(SUBSTITUTE(SUBSTITUTE($H5,"(",""),")","")," ",""),"-","") -> 4730324400 | M5: =SUBSTITUTE(SUBSTITUTE(SUBSTITUTE(SUBSTITUTE($I5,"(",""),")","")," ",""),"-","") | N5: =IF(LEN($L5)=11,$L5,IF(LEN($M5)=11,$M5,"")) | O5: =IF($N5="","",HYPERLINK("https://wa.me/55"&$N5,"Abrir conversa")) | P5: =SUBSTITUTE(INDEX(Mensagens!$D$2:$D$12,MATCH($K5,Mensagens!$A$2:$A$12,0)),"[nome]",$C5) -> Bom dia. Sou o Luis Carlos, da lavanderia do Posto Zandoná, na Ottokar Doerffel, 1489 — a poucos minutos de vocês. Vocês entregam bastante unidade compacta de investidor, e quem coloca o imóvel pra temporada esbarra sempre no mesmo ponto: studio não tem área de serviço, e lençol de hóspede não seca dentro de apartamento. Queria propor que a gente entre no kit de entrega de chaves: cupom de primeira lavagem grátis pro comprador e condição fixa pros proprietários do empreendimento, sem custo nenhum pra construtora. Consigo 15 minutos com quem cuida do relacionamento com os compradores? | Q5: A contatar
A6: 1 | B6: Predio de studios | C6: Curacao Residence | E6: R. Porto Uniao, 1194 | F6: Anita Garibaldi | G6: ate 1 km | J6: plantas de 39 a 163 m2, coworking e piscina | K6: zelador | L6: =SUBSTITUTE(SUBSTITUTE(SUBSTITUTE(SUBSTITUTE($H6,"(",""),")","")," ",""),"-","") | M6: =SUBSTITUTE(SUBSTITUTE(SUBSTITUTE(SUBSTITUTE($I6,"(",""),")","")," ",""),"-","") | N6: =IF(LEN($L6)=11,$L6,IF(LEN($M6)=11,$M6,"")) | O6: =IF($N6="","",HYPERLINK("https://wa.me/55"&$N6,"Abrir conversa")) | P6: =SUBSTITUTE(INDEX(Mensagens!$D$2:$D$12,MATCH($K6,Mensagens!$A$2:$A$12,0)),"[nome]",$C6) -> Bom dia! Sou o Luis Carlos, da lavanderia do Posto Zandoná, aqui na Ottokar Doerffel, 1489 — pertinho do prédio. É autosserviço com máquina industrial, das 6h às 22h. O que mais traz morador daqui é edredom, cobertor e tapete, que não entram na máquina de apartamento. Vi que o Curacao Residence tem bastante studio alugado por temporada, e esse pessoal vira enxoval toda semana. Posso deixar cupons de primeira lavagem grátis na portaria pros moradores, e um cartaz pequeno no mural se o síndico autorizar? | Q6: A contatar
A7: 1 | B7: Predio de studios | C7: Ed. Frame (46 unidades - studios de 38 m2) | E7: R. Concordia, 28 | F7: Anita Garibaldi | G7: ate 1 km | J7: Construtora Viplan - entregue dez/2025 | K7: zelador | L7: =SUBSTITUTE(SUBSTITUTE(SUBSTITUTE(SUBSTITUTE($H7,"(",""),")","")," ",""),"-","") | M7: =SUBSTITUTE(SUBSTITUTE(SUBSTITUTE(SUBSTITUTE($I7,"(",""),")","")," ",""),"-","") | N7: =IF(LEN($L7)=11,$L7,IF(LEN($M7)=11,$M7,"")) | O7: =IF($N7="","",HYPERLINK("https://wa.me/55"&$N7,"Abrir conversa")) | P7: =SUBSTITUTE(INDEX(Mensagens!$D$2:$D$12,MATCH($K7,Mensagens!$A$2:$A$12,0)),"[nome]",$C7) -> Bom dia! Sou o Luis Carlos, da lavanderia do Posto Zandoná, aqui na Ottokar Doerffel, 1489 — pertinho do prédio. É autosserviço com máquina industrial, das 6h às 22h. O que mais traz morador daqui é edredom, cobertor e tapete, que não entram na máquina de apartamento. Vi que o Ed. Frame (46 unidades - studios de 38 m2) tem bastante studio alugado por temporada, e esse pessoal vira enxoval toda semana. Posso deixar cupons de primeira lavagem grátis na portaria pros moradores, e um cartaz pequeno no mural se o síndico autorizar? | Q7: A contatar
A8: 1 | B8: Predio de studios | C8: Ed. WB - Darcy Vargas | E8: perto da Maternidade Darcy Vargas e da Censupeg (confirmar) | F8: Anita Garibaldi | G8: ate 1 km | J8: anuncio ativo 'Apto 203 WB DarcyVargas' | K8: zelador | L8: =SUBSTITUTE(SUBSTITUTE(SUBSTITUTE(SUBSTITUTE($H8,"(",""),")","")," ",""),"-","") | M8: =SUBSTITUTE(SUBSTITUTE(SUBSTITUTE(SUBSTITUTE($I8,"(",""),")","")," ",""),"-","") | N8: =IF(LEN($L8)=11,$L8,IF(LEN($M8)=11,$M8,"")) | O8: =IF($N8="","",HYPERLINK("https://wa.me/55"&$N8,"Abrir conversa")) | P8: =SUBSTITUTE(INDEX(Mensagens!$D$2:$D$12,MATCH($K8,Mensagens!$A$2:$A$12,0)),"[nome]",$C8) -> Bom dia! Sou o Luis Carlos, da lavanderia do Posto Zandoná, aqui na Ottokar Doerffel, 1489 — pertinho do prédio. É autosserviço com máquina industrial, das 6h às 22h. O que mais traz morador daqui é edredom, cobertor e tapete, que não entram na máquina de apartamento. Vi que o Ed. WB - Darcy Vargas tem bastante studio alugado por temporada, e esse pessoal vira enxoval toda semana. Posso deixar cupons de primeira lavagem grátis na portaria pros moradores, e um cartaz pequeno no mural se o síndico autorizar? | Q8: A contatar
A9: 1 | B9: Parceria-chave | C9: Joinville Region Convention & Visitors Bureau | E9: R. Ottokar Doerffel, 1733 | F9: Anita Garibaldi | G9: ate 1 km | J9: visitejoinville.com.br | K9: bureau | L9: =SUBSTITUTE(SUBSTITUTE(SUBSTITUTE(SUBSTITUTE($H9,"(",""),")","")," ",""),"-","") | M9: =SUBSTITUTE(SUBSTITUTE(SUBSTITUTE(SUBSTITUTE($I9,"(",""),")","")," ",""),"-","") | N9: =IF(LEN($L9)=11,$L9,IF(LEN($M9)=11,$M9,"")) | O9: =IF($N9="","",HYPERLINK("https://wa.me/55"&$N9,"Abrir conversa")) | P9: =SUBSTITUTE(INDEX(Mensagens!$D$2:$D$12,MATCH($K9,Mensagens!$A$2:$A$12,0)),"[nome]",$C9) -> Bom dia. Sou o Luis Carlos, da lavanderia do Posto Zandoná, na Ottokar Doerffel, 1489 — somos quase vizinhos de vocês, no 1733. Somos autosserviço com máquinas industriais, das 6h às 22h, e atendemos pousada e hostel pequeno da região central. Queria entender como funciona a relação de vocês com os associados e se cabe uma condição para a rede — pensando no pico do Festival de Dança, quando pousada pequena estoura a capacidade de lavar e precisa de uma válvula de escape perto. Consigo uma conversa de 20 minutos esta semana? | Q9: A contatar
A10: 1 | B10: Estetica/Spa | C10: MS Corpo & Mente Spa | E10: R. Dr. Roberto Koch, 71B - fundos | F10: Atiradores | G10: ate 1 km | K10: beleza | L10: =SUBSTITUTE(SUBSTITUTE(SUBSTITUTE(SUBSTITUTE($H10,"(",""),")","")," ",""),"-","") | M10: =SUBSTITUTE(SUBSTITUTE(SUBSTITUTE(SUBSTITUTE($I10,"(",""),")","")," ",""),"-","") | N10: =IF(LEN($L10)=11,$L10,IF(LEN($M10)=11,$M10,"")) | O10: =IF($N10="","",HYPERLINK("https://wa.me/55"&$N10,"Abrir conversa")) | P10: =SUBSTITUTE(INDEX(Mensagens!$D$2:$D$12,MATCH($K10,Mensagens!$A$2:$A$12,0)),"[nome]",$C10) -> Oi, tudo bem? Sou o Luis Carlos, da lavanderia do Posto Zandoná, aqui na Ottokar Doerffel. Autosserviço com máquina e secadora industrial. Pra salão o ponto é a secadora: toalha que seca no varal fica dura e com cheiro de úmido; na secadora volta macia no mesmo dia. É uma parada de uma hora por semana, e ninguém da equipe precisa levar sacola pra casa. Deixo a primeira lavagem por minha conta pra você comparar. Pode ser? | Q10: A contatar
A11: 1 | B11: Predio de studios | C11: Mingus 897 (54 unidades - smart building) | E11: R. Coronel Santiago, 897 | F11: Anita Garibaldi | G11: ate 1 km | J11: LHW Engenharia | K11: zelador | L11: =SUBSTITUTE(SUBSTITUTE(SUBSTITUTE(SUBSTITUTE($H11,"(",""),")","")," ",""),"-","") | M11: =SUBSTITUTE(SUBSTITUTE(SUBSTITUTE(SUBSTITUTE($I11,"(",""),")","")," ",""),"-","") | N11: =IF(LEN($L11)=11,$L11,IF(LEN($M11)=11,$M11,"")) | O11: =IF($N11="","",HYPERLINK("https://wa.me/55"&$N11,"Abrir conversa")) | P11: =SUBSTITUTE(INDEX(Mensagens!$D$2:$D$12,MATCH($K11,Mensagens!$A$2:$A$12,0)),"[nome]",$C11) -> Bom dia! Sou o Luis Carlos, da lavanderia do Posto Zandoná, aqui na Ottokar Doerffel, 1489 — pertinho do prédio. É autosserviço com máquina industrial, das 6h às 22h. O que mais traz morador daqui é edredom, cobertor e tapete, que não entram na máquina de apartamento. Vi que o Mingus 897 (54 unidades - smart building) tem bastante studio alugado por temporada, e esse pessoal vira enxoval toda semana. Posso deixar cupons de primeira lavagem grátis na portaria pros moradores, e um cartaz pequeno no mural se o síndico autorizar? | Q11: A contatar
A12: 1 | B12: Pet shop | C12: Pet shop - R. Coronel Santiago 870 | E12: R. Coronel Santiago, 870 - sala 2 | F12: Anita Garibaldi | G12: ate 1 km | H12: (47) 98903-9023 | K12: pet | L12: =SUBSTITUTE(SUBSTITUTE(SUBSTITUTE(SUBSTITUTE($H12,"(",""),")","")," ",""),"-","") -> 47989039023 | M12: =SUBSTITUTE(SUBSTITUTE(SUBSTITUTE(SUBSTITUTE($I12,"(",""),")","")," ",""),"-","") | N12: =IF(LEN($L12)=11,$L12,IF(LEN($M12)=11,$M12,"")) -> 47989039023 | O12: =IF($N12="","",HYPERLINK("https://wa.me/55"&$N12,"Abrir conversa")) -> Abrir conversa | P12: =SUBSTITUTE(INDEX(Mensagens!$D$2:$D$12,MATCH($K12,Mensagens!$A$2:$A$12,0)),"[nome]",$C12) -> Oi, tudo bem? Sou o Luis Carlos, da lavanderia aqui do Posto Zandoná, na Ottokar Doerffel — a poucos minutos daqui. Autosserviço, com máquina e secadora industrial. Pra banho e tosa o ganho é a secadora: a toalha sai seca na hora, não fica aquele monte pendurado esperando e azedando. Abrimos às 6h, dá pra resolver antes de abrir a loja, e tem estacionamento na porta. Primeira lavagem por minha conta — quer que eu deixe o cupom aqui? | Q12: A contatar
A13: 1 | B13: Pet shop | C13: Pet shop - R. Ministro Calogeras 1472 | E13: R. Ministro Calogeras, 1472 | F13: Atiradores | G13: ate 1 km | H13: (47) 99738-2080 | I13: (47) 99717-2108 | K13: pet | L13: =SUBSTITUTE(SUBSTITUTE(SUBSTITUTE(SUBSTITUTE($H13,"(",""),")","")," ",""),"-","") -> 47997382080 | M13: =SUBSTITUTE(SUBSTITUTE(SUBSTITUTE(SUBSTITUTE($I13,"(",""),")","")," ",""),"-","") -> 47997172108 | N13: =IF(LEN($L13)=11,$L13,IF(LEN($M13)=11,$M13,"")) -> 47997382080 | O13: =IF($N13="","",HYPERLINK("https://wa.me/55"&$N13,"Abrir conversa")) -> Abrir conversa | P13: =SUBSTITUTE(INDEX(Mensagens!$D$2:$D$12,MATCH($K13,Mensagens!$A$2:$A$12,0)),"[nome]",$C13) -> Oi, tudo bem? Sou o Luis Carlos, da lavanderia aqui do Posto Zandoná, na Ottokar Doerffel — a poucos minutos daqui. Autosserviço, com máquina e secadora industrial. Pra banho e tosa o ganho é a secadora: a toalha sai seca na hora, não fica aquele monte pendurado esperando e azedando. Abrimos às 6h, dá pra resolver antes de abrir a loja, e tem estacionamento na porta. Primeira lavagem por minha conta — quer que eu deixe o cupom aqui? | Q13: A contatar
A14: 1 | B14: Predio de studios | C14: Predio dos 'Estudios 01 a 08' - anfitriao com 3 unidades | E14: coracao do Anita Garibaldi, perto da BR-101 (a localizar) | F14: Anita Garibaldi | G14: ate 1 km | J14: anfitriao Sergio - anuncia Studio 01, Studio 03 e Estudio 08 | K14: zelador | L14: =SUBSTITUTE(SUBSTITUTE(SUBSTITUTE(SUBSTITUTE($H14,"(",""),")","")," ",""),"-","") | M14: =SUBSTITUTE(SUBSTITUTE(SUBSTITUTE(SUBSTITUTE($I14,"(",""),")","")," ",""),"-","") | N14: =IF(LEN($L14)=11,$L14,IF(LEN($M14)=11,$M14,"")) | O14: =IF($N14="","",HYPERLINK("https://wa.me/55"&$N14,"Abrir conversa")) | P14: =SUBSTITUTE(INDEX(Mensagens!$D$2:$D$12,MATCH($K14,Mensagens!$A$2:$A$12,0)),"[nome]",$C14) -> Bom dia! Sou o Luis Carlos, da lavanderia do Posto Zandoná, aqui na Ottokar Doerffel, 1489 — pertinho do prédio. É autosserviço com máquina industrial, das 6h às 22h. O que mais traz morador daqui é edredom, cobertor e tapete, que não entram na máquina de apartamento. Vi que o Predio dos 'Estudios 01 a 08' - anfitriao com 3 unidades tem bastante studio alugado por temporada, e esse pessoal vira enxoval toda semana. Posso deixar cupons de primeira lavagem grátis na portaria pros moradores, e um cartaz pequeno no mural se o síndico autorizar? | Q14: A contatar
A15: 2 | B15: Academia | C15: Academia Getulio | E15: R. Dr. Placido Gomes, 308 | F15: Anita Garibaldi | G15: ate 1 km | K15: academia | L15: =SUBSTITUTE(SUBSTITUTE(SUBSTITUTE(SUBSTITUTE($H15,"(",""),")","")," ",""),"-","") | M15: =SUBSTITUTE(SUBSTITUTE(SUBSTITUTE(SUBSTITUTE($I15,"(",""),")","")," ",""),"-","") | N15: =IF(LEN($L15)=11,$L15,IF(LEN($M15)=11,$M15,"")) | O15: =IF($N15="","",HYPERLINK("https://wa.me/55"&$N15,"Abrir conversa")) | P15: =SUBSTITUTE(INDEX(Mensagens!$D$2:$D$12,MATCH($K15,Mensagens!$A$2:$A$12,0)),"[nome]",$C15) -> Oi! Sou o Luis Carlos, da lavanderia do Posto Zandoná, aqui na Ottokar Doerffel. Autosserviço com máquina e secadora industrial: toalha de treino e pano de higienização lavam e secam numa parada só — sem máquina rodando no intervalo e sem ninguém da recepção cuidando disso. Das 6h às 22h, com estacionamento na porta. Primeira lavagem por minha conta pra você ver o resultado. Quando fica bom testar? | Q15: A contatar
A16: 2 | B16: Academia | C16: Academia Ph.D Sports Joinville | E16: R. Eugenio Moreira, 331 | F16: Anita Garibaldi | G16: ate 1 km | K16: academia | L16: =SUBSTITUTE(SUBSTITUTE(SUBSTITUTE(SUBSTITUTE($H16,"(",""),")","")," ",""),"-","") | M16: =SUBSTITUTE(SUBSTITUTE(SUBSTITUTE(SUBSTITUTE($I16,"(",""),")","")," ",""),"-","") | N16: =IF(LEN($L16)=11,$L16,IF(LEN($M16)=11,$M16,"")) | O16: =IF($N16="","",HYPERLINK("https://wa.me/55"&$N16,"Abrir conversa")) | P16: =SUBSTITUTE(INDEX(Mensagens!$D$2:$D$12,MATCH($K16,Mensagens!$A$2:$A$12,0)),"[nome]",$C16) -> Oi! Sou o Luis Carlos, da lavanderia do Posto Zandoná, aqui na Ottokar Doerffel. Autosserviço com máquina e secadora industrial: toalha de treino e pano de higienização lavam e secam numa parada só — sem máquina rodando no intervalo e sem ninguém da recepção cuidando disso. Das 6h às 22h, com estacionamento na porta. Primeira lavagem por minha conta pra você ver o resultado. Quando fica bom testar? | Q16: A contatar
A17: 2 | B17: Barbearia/Salao | C17: Espaco Barbearia | E17: R. Anita Garibaldi, 961 | F17: Anita Garibaldi | G17: ate 1 km | K17: beleza | L17: =SUBSTITUTE(SUBSTITUTE(SUBSTITUTE(SUBSTITUTE($H17,"(",""),")","")," ",""),"-","") | M17: =SUBSTITUTE(SUBSTITUTE(SUBSTITUTE(SUBSTITUTE($I17,"(",""),")","")," ",""),"-","") | N17: =IF(LEN($L17)=11,$L17,IF(LEN($M17)=11,$M17,"")) | O17: =IF($N17="","",HYPERLINK("https://wa.me/55"&$N17,"Abrir conversa")) | P17: =SUBSTITUTE(INDEX(Mensagens!$D$2:$D$12,MATCH($K17,Mensagens!$A$2:$A$12,0)),"[nome]",$C17) -> Oi, tudo bem? Sou o Luis Carlos, da lavanderia do Posto Zandoná, aqui na Ottokar Doerffel. Autosserviço com máquina e secadora industrial. Pra salão o ponto é a secadora: toalha que seca no varal fica dura e com cheiro de úmido; na secadora volta macia no mesmo dia. É uma parada de uma hora por semana, e ninguém da equipe precisa levar sacola pra casa. Deixo a primeira lavagem por minha conta pra você comparar. Pode ser? | Q17: A contatar
A18: 2 | B18: Estetica/Spa | C18: Homenz Joinville (estetica masculina) | E18: R. Anita Garibaldi, 413 - loja 02 | F18: Anita Garibaldi | G18: ate 1 km | J18: homenzjoinville.com.br | K18: beleza | L18: =SUBSTITUTE(SUBSTITUTE(SUBSTITUTE(SUBSTITUTE($H18,"(",""),")","")," ",""),"-","") | M18: =SUBSTITUTE(SUBSTITUTE(SUBSTITUTE(SUBSTITUTE($I18,"(",""),")","")," ",""),"-","") | N18: =IF(LEN($L18)=11,$L18,IF(LEN($M18)=11,$M18,"")) | O18: =IF($N18="","",HYPERLINK("https://wa.me/55"&$N18,"Abrir conversa")) | P18: =SUBSTITUTE(INDEX(Mensagens!$D$2:$D$12,MATCH($K18,Mensagens!$A$2:$A$12,0)),"[nome]",$C18) -> Oi, tudo bem? Sou o Luis Carlos, da lavanderia do Posto Zandoná, aqui na Ottokar Doerffel. Autosserviço com máquina e secadora industrial. Pra salão o ponto é a secadora: toalha que seca no varal fica dura e com cheiro de úmido; na secadora volta macia no mesmo dia. É uma parada de uma hora por semana, e ninguém da equipe precisa levar sacola pra casa. Deixo a primeira lavagem por minha conta pra você comparar. Pode ser? | Q18: A contatar
A19: 2 | B19: Estetica/Spa | C19: Jana Fantoni Clinica de Estetica | E19: R. Padre Kolb, 1547 | F19: Anita Garibaldi | G19: ate 1 km | J19: janafantoni.com.br | K19: beleza | L19: =SUBSTITUTE(SUBSTITUTE(SUBSTITUTE(SUBSTITUTE($H19,"(",""),")","")," ",""),"-","") | M19: =SUBSTITUTE(SUBSTITUTE(SUBSTITUTE(SUBSTITUTE($I19,"(",""),")","")," ",""),"-","") | N19: =IF(LEN($L19)=11,$L19,IF(LEN($M19)=11,$M19,"")) | O19: =IF($N19="","",HYPERLINK("https://wa.me/55"&$N19,"Abrir conversa")) | P19: =SUBSTITUTE(INDEX(Mensagens!$D$2:$D$12,MATCH($K19,Mensagens!$A$2:$A$12,0)),"[nome]",$C19) -> Oi, tudo bem? Sou o Luis Carlos, da lavanderia do Posto Zandoná, aqui na Ottokar Doerffel. Autosserviço com máquina e secadora industrial. Pra salão o ponto é a secadora: toalha que seca no varal fica dura e com cheiro de úmido; na secadora volta macia no mesmo dia. É uma parada de uma hora por semana, e ninguém da equipe precisa levar sacola pra casa. Deixo a primeira lavagem por minha conta pra você comparar. Pode ser? | Q19: A contatar
A20: 2 | B20: Academia | C20: Noxii Live Center | E20: R. Pernambuco, 574 | F20: Atiradores | G20: ate 1 km | K20: academia | L20: =SUBSTITUTE(SUBSTITUTE(SUBSTITUTE(SUBSTITUTE($H20,"(",""),")","")," ",""),"-","") | M20: =SUBSTITUTE(SUBSTITUTE(SUBSTITUTE(SUBSTITUTE($I20,"(",""),")","")," ",""),"-","") | N20: =IF(LEN($L20)=11,$L20,IF(LEN($M20)=11,$M20,"")) | O20: =IF($N20="","",HYPERLINK("https://wa.me/55"&$N20,"Abrir conversa")) | P20: =SUBSTITUTE(INDEX(Mensagens!$D$2:$D$12,MATCH($K20,Mensagens!$A$2:$A$12,0)),"[nome]",$C20) -> Oi! Sou o Luis Carlos, da lavanderia do Posto Zandoná, aqui na Ottokar Doerffel. Autosserviço com máquina e secadora industrial: toalha de treino e pano de higienização lavam e secam numa parada só — sem máquina rodando no intervalo e sem ninguém da recepção cuidando disso. Das 6h às 22h, com estacionamento na porta. Primeira lavagem por minha conta pra você ver o resultado. Quando fica bom testar? | Q20: A contatar
A21: 2 | B21: Predio de studios | C21: Torre Morion | E21: Anita Garibaldi (a confirmar) | F21: Anita Garibaldi | G21: ate 1 km | J21: obra da EJF Construtora - anfitria Grasiela ('Home Stays') | K21: zelador | L21: =SUBSTITUTE(SUBSTITUTE(SUBSTITUTE(SUBSTITUTE($H21,"(",""),")","")," ",""),"-","") | M21: =SUBSTITUTE(SUBSTITUTE(SUBSTITUTE(SUBSTITUTE($I21,"(",""),")","")," ",""),"-","") | N21: =IF(LEN($L21)=11,$L21,IF(LEN($M21)=11,$M21,"")) | O21: =IF($N21="","",HYPERLINK("https://wa.me/55"&$N21,"Abrir conversa")) | P21: =SUBSTITUTE(INDEX(Mensagens!$D$2:$D$12,MATCH($K21,Mensagens!$A$2:$A$12,0)),"[nome]",$C21) -> Bom dia! Sou o Luis Carlos, da lavanderia do Posto Zandoná, aqui na Ottokar Doerffel, 1489 — pertinho do prédio. É autosserviço com máquina industrial, das 6h às 22h. O que mais traz morador daqui é edredom, cobertor e tapete, que não entram na máquina de apartamento. Vi que o Torre Morion tem bastante studio alugado por temporada, e esse pessoal vira enxoval toda semana. Posso deixar cupons de primeira lavagem grátis na portaria pros moradores, e um cartaz pequeno no mural se o síndico autorizar? | Q21: A contatar
A22: 3 | B22: Pet shop | C22: ECL Pet Shop | E22: R. Rio Grande do Sul | F22: Anita Garibaldi | G22: ate 1 km | K22: pet | L22: =SUBSTITUTE(SUBSTITUTE(SUBSTITUTE(SUBSTITUTE($H22,"(",""),")","")," ",""),"-","") | M22: =SUBSTITUTE(SUBSTITUTE(SUBSTITUTE(SUBSTITUTE($I22,"(",""),")","")," ",""),"-","") | N22: =IF(LEN($L22)=11,$L22,IF(LEN($M22)=11,$M22,"")) | O22: =IF($N22="","",HYPERLINK("https://wa.me/55"&$N22,"Abrir conversa")) | P22: =SUBSTITUTE(INDEX(Mensagens!$D$2:$D$12,MATCH($K22,Mensagens!$A$2:$A$12,0)),"[nome]",$C22) -> Oi, tudo bem? Sou o Luis Carlos, da lavanderia aqui do Posto Zandoná, na Ottokar Doerffel — a poucos minutos daqui. Autosserviço, com máquina e secadora industrial. Pra banho e tosa o ganho é a secadora: a toalha sai seca na hora, não fica aquele monte pendurado esperando e azedando. Abrimos às 6h, dá pra resolver antes de abrir a loja, e tem estacionamento na porta. Primeira lavagem por minha conta — quer que eu deixe o cupom aqui? | Q22: A contatar
A23: 3 | B23: Predio de studios | C23: Wave Residence (studios de 28 m2 - entrega jul/2028) | E23: divisa Anita Garibaldi / Atiradores | F23: Anita Garibaldi | G23: ate 1 km | J23: obra desde jul/2025, a partir de R$ 282 mil | K23: zelador | L23: =SUBSTITUTE(SUBSTITUTE(SUBSTITUTE(SUBSTITUTE($H23,"(",""),")","")," ",""),"-","") | M23: =SUBSTITUTE(SUBSTITUTE(SUBSTITUTE(SUBSTITUTE($I23,"(",""),")","")," ",""),"-","") | N23: =IF(LEN($L23)=11,$L23,IF(LEN($M23)=11,$M23,"")) | O23: =IF($N23="","",HYPERLINK("https://wa.me/55"&$N23,"Abrir conversa")) | P23: =SUBSTITUTE(INDEX(Mensagens!$D$2:$D$12,MATCH($K23,Mensagens!$A$2:$A$12,0)),"[nome]",$C23) -> Bom dia! Sou o Luis Carlos, da lavanderia do Posto Zandoná, aqui na Ottokar Doerffel, 1489 — pertinho do prédio. É autosserviço com máquina industrial, das 6h às 22h. O que mais traz morador daqui é edredom, cobertor e tapete, que não entram na máquina de apartamento. Vi que o Wave Residence (studios de 28 m2 - entrega jul/2028) tem bastante studio alugado por temporada, e esse pessoal vira enxoval toda semana. Posso deixar cupons de primeira lavagem grátis na portaria pros moradores, e um cartaz pequeno no mural se o síndico autorizar? | Q23: A contatar
A24: 1 | B24: Hospedagem | C24: American Hostel | D24: 5 quartos | E24: R. Capinzal, 584 | F24: America | G24: 1-3 km | H24: (47) 99918-8474 | K24: pousada | L24: =SUBSTITUTE(SUBSTITUTE(SUBSTITUTE(SUBSTITUTE($H24,"(",""),")","")," ",""),"-","") -> 47999188474 | M24: =SUBSTITUTE(SUBSTITUTE(SUBSTITUTE(SUBSTITUTE($I24,"(",""),")","")," ",""),"-","") | N24: =IF(LEN($L24)=11,$L24,IF(LEN($M24)=11,$M24,"")) -> 47999188474 | O24: =IF($N24="","",HYPERLINK("https://wa.me/55"&$N24,"Abrir conversa")) -> Abrir conversa | P24: =SUBSTITUTE(INDEX(Mensagens!$D$2:$D$12,MATCH($K24,Mensagens!$A$2:$A$12,0)),"[nome]",$C24) -> Bom dia, American Hostel! Aqui é o Luis Carlos, da lavanderia do Posto Zandoná, na Ottokar Doerffel, 1489. É autosserviço — vocês mesmos usam as máquinas — mas são industriais: o enxoval de uma diária inteira vai de uma vez e sai seco na secadora em cerca de uma hora. Nada de lençol pendurado três dias no inverno. Abrimos das 6h às 22h, com estacionamento na porta. E para empresa eu faturo no mês, com nota. Queria te dar a primeira lavagem por conta da casa, pra vocês medirem quanto tempo economiza. Posso deixar o cupom aí? | Q24: A contatar
A25: 1 | B25: Predio de studios | C25: Edificio Prinz Mercure (zelador/sindico) | F25: America | G25: 1-3 km | K25: zelador | L25: =SUBSTITUTE(SUBSTITUTE(SUBSTITUTE(SUBSTITUTE($H25,"(",""),")","")," ",""),"-","") | M25: =SUBSTITUTE(SUBSTITUTE(SUBSTITUTE(SUBSTITUTE($I25,"(",""),")","")," ",""),"-","") | N25: =IF(LEN($L25)=11,$L25,IF(LEN($M25)=11,$M25,"")) | O25: =IF($N25="","",HYPERLINK("https://wa.me/55"&$N25,"Abrir conversa")) | P25: =SUBSTITUTE(INDEX(Mensagens!$D$2:$D$12,MATCH($K25,Mensagens!$A$2:$A$12,0)),"[nome]",$C25) -> Bom dia! Sou o Luis Carlos, da lavanderia do Posto Zandoná, aqui na Ottokar Doerffel, 1489 — pertinho do prédio. É autosserviço com máquina industrial, das 6h às 22h. O que mais traz morador daqui é edredom, cobertor e tapete, que não entram na máquina de apartamento. Vi que o Edificio Prinz Mercure (zelador/sindico) tem bastante studio alugado por temporada, e esse pessoal vira enxoval toda semana. Posso deixar cupons de primeira lavagem grátis na portaria pros moradores, e um cartaz pequeno no mural se o síndico autorizar? | Q25: A contatar
A26: 1 | B26: Short stay/operador | C26: IVVI - flats de short stay | E26: R. Otto Boehm (numero a confirmar) | F26: Centro / America | G26: 1-3 km | J26: anfitriao 'IVVI Gestao e Tecnologia' no Airbnb | K26: gestora | L26: =SUBSTITUTE(SUBSTITUTE(SUBSTITUTE(SUBSTITUTE($H26,"(",""),")","")," ",""),"-","") | M26: =SUBSTITUTE(SUBSTITUTE(SUBSTITUTE(SUBSTITUTE($I26,"(",""),")","")," ",""),"-","") | N26: =IF(LEN($L26)=11,$L26,IF(LEN($M26)=11,$M26,"")) | O26: =IF($N26="","",HYPERLINK("https://wa.me/55"&$N26,"Abrir conversa")) | P26: =SUBSTITUTE(INDEX(Mensagens!$D$2:$D$12,MATCH($K26,Mensagens!$A$2:$A$12,0)),"[nome]",$C26) -> Bom dia, IVVI - flats de short stay. Sou o Luis Carlos, da lavanderia do Posto Zandoná (Ottokar Doerffel, 1489, Anita Garibaldi). Autosserviço com máquinas industriais: a equipe de limpeza de vocês resolve o enxoval de vários imóveis numa parada só — lava e seca em cerca de uma hora, das 6h às 22h, com estacionamento na porta. Pra quem administra carteira eu abro conta faturada: a equipe usa as máquinas o mês todo e vocês recebem uma nota só no fechamento, sem ninguém pagando do próprio bolso e pedindo reembolso depois. Topa testar com um imóvel? A primeira lavagem é por minha conta. | Q26: A contatar
A27: 1 | B27: Hospedagem | C27: Pousada Ipanema | D27: a confirmar | E27: R. Paraiba, 912 | F27: Anita Garibaldi | G27: 1-3 km | H27: (47) 3227-8462 | K27: pousada | L27: =SUBSTITUTE(SUBSTITUTE(SUBSTITUTE(SUBSTITUTE($H27,"(",""),")","")," ",""),"-","") -> 4732278462 | M27: =SUBSTITUTE(SUBSTITUTE(SUBSTITUTE(SUBSTITUTE($I27,"(",""),")","")," ",""),"-","") | N27: =IF(LEN($L27)=11,$L27,IF(LEN($M27)=11,$M27,"")) | O27: =IF($N27="","",HYPERLINK("https://wa.me/55"&$N27,"Abrir conversa")) | P27: =SUBSTITUTE(INDEX(Mensagens!$D$2:$D$12,MATCH($K27,Mensagens!$A$2:$A$12,0)),"[nome]",$C27) -> Bom dia, Pousada Ipanema! Aqui é o Luis Carlos, da lavanderia do Posto Zandoná, na Ottokar Doerffel, 1489. É autosserviço — vocês mesmos usam as máquinas — mas são industriais: o enxoval de uma diária inteira vai de uma vez e sai seco na secadora em cerca de uma hora. Nada de lençol pendurado três dias no inverno. Abrimos das 6h às 22h, com estacionamento na porta. E para empresa eu faturo no mês, com nota. Queria te dar a primeira lavagem por conta da casa, pra vocês medirem quanto tempo economiza. Posso deixar o cupom aí? | Q27: A contatar
A28: 1 | B28: Hospedagem | C28: Pousada Joinvilense | D28: a confirmar | E28: R. Corupa, 267 | F28: Anita Garibaldi | G28: 1-3 km | H28: (47) 98816-2760 | K28: pousada | L28: =SUBSTITUTE(SUBSTITUTE(SUBSTITUTE(SUBSTITUTE($H28,"(",""),")","")," ",""),"-","") -> 47988162760 | M28: =SUBSTITUTE(SUBSTITUTE(SUBSTITUTE(SUBSTITUTE($I28,"(",""),")","")," ",""),"-","") | N28: =IF(LEN($L28)=11,$L28,IF(LEN($M28)=11,$M28,"")) -> 47988162760 | O28: =IF($N28="","",HYPERLINK("https://wa.me/55"&$N28,"Abrir conversa")) -> Abrir conversa | P28: =SUBSTITUTE(INDEX(Mensagens!$D$2:$D$12,MATCH($K28,Mensagens!$A$2:$A$12,0)),"[nome]",$C28) -> Bom dia, Pousada Joinvilense! Aqui é o Luis Carlos, da lavanderia do Posto Zandoná, na Ottokar Doerffel, 1489. É autosserviço — vocês mesmos usam as máquinas — mas são industriais: o enxoval de uma diária inteira vai de uma vez e sai seco na secadora em cerca de uma hora. Nada de lençol pendurado três dias no inverno. Abrimos das 6h às 22h, com estacionamento na porta. E para empresa eu faturo no mês, com nota. Queria te dar a primeira lavagem por conta da casa, pra vocês medirem quanto tempo economiza. Posso deixar o cupom aí? | Q28: A contatar
A29: 1 | B29: Lar de idosos | C29: Residencial Geriatrico Hera | E29: R. Dr. Placido Olimpio de Oliveira, 256 | F29: Bucarein | G29: 1-3 km | H29: (47) 99624-0990 | K29: ilpi | L29: =SUBSTITUTE(SUBSTITUTE(SUBSTITUTE(SUBSTITUTE($H29,"(",""),")","")," ",""),"-","") -> 47996240990 | M29: =SUBSTITUTE(SUBSTITUTE(SUBSTITUTE(SUBSTITUTE($I29,"(",""),")","")," ",""),"-","") | N29: =IF(LEN($L29)=11,$L29,IF(LEN($M29)=11,$M29,"")) -> 47996240990 | O29: =IF($N29="","",HYPERLINK("https://wa.me/55"&$N29,"Abrir conversa")) -> Abrir conversa | P29: =SUBSTITUTE(INDEX(Mensagens!$D$2:$D$12,MATCH($K29,Mensagens!$A$2:$A$12,0)),"[nome]",$C29) -> Bom dia, eu gostaria de falar com a administração, por favor. Somos a lavanderia do Posto Zandoná, na Ottokar Doerffel. Autosserviço com máquinas industriais, das 6h às 22h, e trabalhamos com conta faturada mensal e nota fiscal para instituições. A ideia é simples: em vez de manter máquina doméstica rodando o dia inteiro, a funcionária traz o enxoval duas ou três vezes por semana e resolve tudo de uma vez — inclusive cobertor e edredom, que é o que mais trava lavanderia interna no inverno. Posso passar os valores pra vocês compararem com o custo cheio de lavar internamente: energia, água, produto, manutenção da máquina e as horas da funcionária? | Q29: A contatar
A30: 2 | B30: Predio de studios | C30: AP London | E30: Centro de Joinville (a confirmar) | F30: Centro | G30: 1-3 km | J30: anuncio ativo 'AP London - Centro de Joinville' | K30: zelador | L30: =SUBSTITUTE(SUBSTITUTE(SUBSTITUTE(SUBSTITUTE($H30,"(",""),")","")," ",""),"-","") | M30: =SUBSTITUTE(SUBSTITUTE(SUBSTITUTE(SUBSTITUTE($I30,"(",""),")","")," ",""),"-","") | N30: =IF(LEN($L30)=11,$L30,IF(LEN($M30)=11,$M30,"")) | O30: =IF($N30="","",HYPERLINK("https://wa.me/55"&$N30,"Abrir conversa")) | P30: =SUBSTITUTE(INDEX(Mensagens!$D$2:$D$12,MATCH($K30,Mensagens!$A$2:$A$12,0)),"[nome]",$C30) -> Bom dia! Sou o Luis Carlos, da lavanderia do Posto Zandoná, aqui na Ottokar Doerffel, 1489 — pertinho do prédio. É autosserviço com máquina industrial, das 6h às 22h. O que mais traz morador daqui é edredom, cobertor e tapete, que não entram na máquina de apartamento. Vi que o AP London tem bastante studio alugado por temporada, e esse pessoal vira enxoval toda semana. Posso deixar cupons de primeira lavagem grátis na portaria pros moradores, e um cartaz pequeno no mural se o síndico autorizar? | Q30: A contatar
A31: 2 | B31: Restaurante | C31: Biergarten | E31: R. Visconde de Taunay, 1183 | F31: Centro | G31: 1-3 km | H31: (47) 3028-3771 | K31: restaurante | L31: =SUBSTITUTE(SUBSTITUTE(SUBSTITUTE(SUBSTITUTE($H31,"(",""),")","")," ",""),"-","") -> 4730283771 | M31: =SUBSTITUTE(SUBSTITUTE(SUBSTITUTE(SUBSTITUTE($I31,"(",""),")","")," ",""),"-","") | N31: =IF(LEN($L31)=11,$L31,IF(LEN($M31)=11,$M31,"")) | O31: =IF($N31="","",HYPERLINK("https://wa.me/55"&$N31,"Abrir conversa")) | P31: =SUBSTITUTE(INDEX(Mensagens!$D$2:$D$12,MATCH($K31,Mensagens!$A$2:$A$12,0)),"[nome]",$C31) -> Oi, posso falar com o responsável? Sou o Luis Carlos, da lavanderia do Posto Zandoná, na Ottokar Doerffel, 1489. Autosserviço com máquinas industriais, das 6h às 22h — pega antes de abrir e depois de fechar. Pano de copa, avental e toalha de mesa lavam e secam numa parada só. O que costuma resolver é não depender mais de alguém levar pra lavar em casa no fim de semana. E pra empresa eu faturo no mês, com nota. Quer testar com a primeira lavagem por minha conta? | Q31: A contatar
A32: 2 | B32: Restaurante | C32: Fattori da Visconde | E32: R. Visconde de Taunay, 1136 | F32: Centro | G32: 1-3 km | H32: (47) 3027-7727 | K32: restaurante | L32: =SUBSTITUTE(SUBSTITUTE(SUBSTITUTE(SUBSTITUTE($H32,"(",""),")","")," ",""),"-","") -> 4730277727 | M32: =SUBSTITUTE(SUBSTITUTE(SUBSTITUTE(SUBSTITUTE($I32,"(",""),")","")," ",""),"-","") | N32: =IF(LEN($L32)=11,$L32,IF(LEN($M32)=11,$M32,"")) | O32: =IF($N32="","",HYPERLINK("https://wa.me/55"&$N32,"Abrir conversa")) | P32: =SUBSTITUTE(INDEX(Mensagens!$D$2:$D$12,MATCH($K32,Mensagens!$A$2:$A$12,0)),"[nome]",$C32) -> Oi, posso falar com o responsável? Sou o Luis Carlos, da lavanderia do Posto Zandoná, na Ottokar Doerffel, 1489. Autosserviço com máquinas industriais, das 6h às 22h — pega antes de abrir e depois de fechar. Pano de copa, avental e toalha de mesa lavam e secam numa parada só. O que costuma resolver é não depender mais de alguém levar pra lavar em casa no fim de semana. E pra empresa eu faturo no mês, com nota. Quer testar com a primeira lavagem por minha conta? | Q32: A contatar
A33: 2 | B33: Pet shop | C33: Pet shop - R. Aquidaban 730 | E33: R. Aquidaban, 730 | F33: America | G33: 1-3 km | H33: (47) 3432-1792 | I33: (47) 99751-5499 | K33: pet | L33: =SUBSTITUTE(SUBSTITUTE(SUBSTITUTE(SUBSTITUTE($H33,"(",""),")","")," ",""),"-","") -> 4734321792 | M33: =SUBSTITUTE(SUBSTITUTE(SUBSTITUTE(SUBSTITUTE($I33,"(",""),")","")," ",""),"-","") -> 47997515499 | N33: =IF(LEN($L33)=11,$L33,IF(LEN($M33)=11,$M33,"")) -> 47997515499 | O33: =IF($N33="","",HYPERLINK("https://wa.me/55"&$N33,"Abrir conversa")) -> Abrir conversa | P33: =SUBSTITUTE(INDEX(Mensagens!$D$2:$D$12,MATCH($K33,Mensagens!$A$2:$A$12,0)),"[nome]",$C33) -> Oi, tudo bem? Sou o Luis Carlos, da lavanderia aqui do Posto Zandoná, na Ottokar Doerffel — a poucos minutos daqui. Autosserviço, com máquina e secadora industrial. Pra banho e tosa o ganho é a secadora: a toalha sai seca na hora, não fica aquele monte pendurado esperando e azedando. Abrimos às 6h, dá pra resolver antes de abrir a loja, e tem estacionamento na porta. Primeira lavagem por minha conta — quer que eu deixe o cupom aqui? | Q33: A contatar
A34: 2 | B34: Pet shop | C34: Pet shop - R. Jaragua 910 | E34: R. Jaragua, 910 - salas 1 e 2 | F34: America | G34: 1-3 km | H34: (47) 3023-7320 | I34: (47) 99783-0156 | K34: pet | L34: =SUBSTITUTE(SUBSTITUTE(SUBSTITUTE(SUBSTITUTE($H34,"(",""),")","")," ",""),"-","") -> 4730237320 | M34: =SUBSTITUTE(SUBSTITUTE(SUBSTITUTE(SUBSTITUTE($I34,"(",""),")","")," ",""),"-","") -> 47997830156 | N34: =IF(LEN($L34)=11,$L34,IF(LEN($M34)=11,$M34,"")) -> 47997830156 | O34: =IF($N34="","",HYPERLINK("https://wa.me/55"&$N34,"Abrir conversa")) -> Abrir conversa | P34: =SUBSTITUTE(INDEX(Mensagens!$D$2:$D$12,MATCH($K34,Mensagens!$A$2:$A$12,0)),"[nome]",$C34) -> Oi, tudo bem? Sou o Luis Carlos, da lavanderia aqui do Posto Zandoná, na Ottokar Doerffel — a poucos minutos daqui. Autosserviço, com máquina e secadora industrial. Pra banho e tosa o ganho é a secadora: a toalha sai seca na hora, não fica aquele monte pendurado esperando e azedando. Abrimos às 6h, dá pra resolver antes de abrir a loja, e tem estacionamento na porta. Primeira lavagem por minha conta — quer que eu deixe o cupom aqui? | Q34: A contatar
A35: 2 | B35: Restaurante | C35: Pizza na Pedra | E35: R. Visconde de Taunay, 1223 | F35: Centro | G35: 1-3 km | H35: (47) 3028-1868 | K35: restaurante | L35: =SUBSTITUTE(SUBSTITUTE(SUBSTITUTE(SUBSTITUTE($H35,"(",""),")","")," ",""),"-","") -> 4730281868 | M35: =SUBSTITUTE(SUBSTITUTE(SUBSTITUTE(SUBSTITUTE($I35,"(",""),")","")," ",""),"-","") | N35: =IF(LEN($L35)=11,$L35,IF(LEN($M35)=11,$M35,"")) | O35: =IF($N35="","",HYPERLINK("https://wa.me/55"&$N35,"Abrir conversa")) | P35: =SUBSTITUTE(INDEX(Mensagens!$D$2:$D$12,MATCH($K35,Mensagens!$A$2:$A$12,0)),"[nome]",$C35) -> Oi, posso falar com o responsável? Sou o Luis Carlos, da lavanderia do Posto Zandoná, na Ottokar Doerffel, 1489. Autosserviço com máquinas industriais, das 6h às 22h — pega antes de abrir e depois de fechar. Pano de copa, avental e toalha de mesa lavam e secam numa parada só. O que costuma resolver é não depender mais de alguém levar pra lavar em casa no fim de semana. E pra empresa eu faturo no mês, com nota. Quer testar com a primeira lavagem por minha conta? | Q35: A contatar
A36: 2 | B36: Barbearia/Salao | C36: Tiao Cabeleireiros | E36: Av. Getulio Vargas, 1446 - s. 62/63 | F36: Anita Garibaldi | G36: 1-3 km | K36: beleza | L36: =SUBSTITUTE(SUBSTITUTE(SUBSTITUTE(SUBSTITUTE($H36,"(",""),")","")," ",""),"-","") | M36: =SUBSTITUTE(SUBSTITUTE(SUBSTITUTE(SUBSTITUTE($I36,"(",""),")","")," ",""),"-","") | N36: =IF(LEN($L36)=11,$L36,IF(LEN($M36)=11,$M36,"")) | O36: =IF($N36="","",HYPERLINK("https://wa.me/55"&$N36,"Abrir conversa")) | P36: =SUBSTITUTE(INDEX(Mensagens!$D$2:$D$12,MATCH($K36,Mensagens!$A$2:$A$12,0)),"[nome]",$C36) -> Oi, tudo bem? Sou o Luis Carlos, da lavanderia do Posto Zandoná, aqui na Ottokar Doerffel. Autosserviço com máquina e secadora industrial. Pra salão o ponto é a secadora: toalha que seca no varal fica dura e com cheiro de úmido; na secadora volta macia no mesmo dia. É uma parada de uma hora por semana, e ninguém da equipe precisa levar sacola pra casa. Deixo a primeira lavagem por minha conta pra você comparar. Pode ser? | Q36: A contatar
A37: 2 | B37: Pet shop | C37: Vita Vet Clinica Veterinaria e Pet Shop | E37: R. Otto Boehm, 847 | F37: America | G37: 1-3 km | K37: pet | L37: =SUBSTITUTE(SUBSTITUTE(SUBSTITUTE(SUBSTITUTE($H37,"(",""),")","")," ",""),"-","") | M37: =SUBSTITUTE(SUBSTITUTE(SUBSTITUTE(SUBSTITUTE($I37,"(",""),")","")," ",""),"-","") | N37: =IF(LEN($L37)=11,$L37,IF(LEN($M37)=11,$M37,"")) | O37: =IF($N37="","",HYPERLINK("https://wa.me/55"&$N37,"Abrir conversa")) | P37: =SUBSTITUTE(INDEX(Mensagens!$D$2:$D$12,MATCH($K37,Mensagens!$A$2:$A$12,0)),"[nome]",$C37) -> Oi, tudo bem? Sou o Luis Carlos, da lavanderia aqui do Posto Zandoná, na Ottokar Doerffel — a poucos minutos daqui. Autosserviço, com máquina e secadora industrial. Pra banho e tosa o ganho é a secadora: a toalha sai seca na hora, não fica aquele monte pendurado esperando e azedando. Abrimos às 6h, dá pra resolver antes de abrir a loja, e tem estacionamento na porta. Primeira lavagem por minha conta — quer que eu deixe o cupom aqui? | Q37: A contatar
A38: 3 | B38: Restaurante | C38: D.O.C. Cucina e Co | E38: R. Visconde de Taunay, 146 | F38: Centro | G38: 1-3 km | H38: (47) 3025-3822 | K38: restaurante | L38: =SUBSTITUTE(SUBSTITUTE(SUBSTITUTE(SUBSTITUTE($H38,"(",""),")","")," ",""),"-","") -> 4730253822 | M38: =SUBSTITUTE(SUBSTITUTE(SUBSTITUTE(SUBSTITUTE($I38,"(",""),")","")," ",""),"-","") | N38: =IF(LEN($L38)=11,$L38,IF(LEN($M38)=11,$M38,"")) | O38: =IF($N38="","",HYPERLINK("https://wa.me/55"&$N38,"Abrir conversa")) | P38: =SUBSTITUTE(INDEX(Mensagens!$D$2:$D$12,MATCH($K38,Mensagens!$A$2:$A$12,0)),"[nome]",$C38) -> Oi, posso falar com o responsável? Sou o Luis Carlos, da lavanderia do Posto Zandoná, na Ottokar Doerffel, 1489. Autosserviço com máquinas industriais, das 6h às 22h — pega antes de abrir e depois de fechar. Pano de copa, avental e toalha de mesa lavam e secam numa parada só. O que costuma resolver é não depender mais de alguém levar pra lavar em casa no fim de semana. E pra empresa eu faturo no mês, com nota. Quer testar com a primeira lavagem por minha conta? | Q38: A contatar
A39: 3 | B39: Restaurante | C39: Hosu Sushi | E39: R. Visconde de Taunay, 572 B | F39: Centro | G39: 1-3 km | H39: (47) 98838-2575 | K39: restaurante | L39: =SUBSTITUTE(SUBSTITUTE(SUBSTITUTE(SUBSTITUTE($H39,"(",""),")","")," ",""),"-","") -> 47988382575 | M39: =SUBSTITUTE(SUBSTITUTE(SUBSTITUTE(SUBSTITUTE($I39,"(",""),")","")," ",""),"-","") | N39: =IF(LEN($L39)=11,$L39,IF(LEN($M39)=11,$M39,"")) -> 47988382575 | O39: =IF($N39="","",HYPERLINK("https://wa.me/55"&$N39,"Abrir conversa")) -> Abrir conversa | P39: =SUBSTITUTE(INDEX(Mensagens!$D$2:$D$12,MATCH($K39,Mensagens!$A$2:$A$12,0)),"[nome]",$C39) -> Oi, posso falar com o responsável? Sou o Luis Carlos, da lavanderia do Posto Zandoná, na Ottokar Doerffel, 1489. Autosserviço com máquinas industriais, das 6h às 22h — pega antes de abrir e depois de fechar. Pano de copa, avental e toalha de mesa lavam e secam numa parada só. O que costuma resolver é não depender mais de alguém levar pra lavar em casa no fim de semana. E pra empresa eu faturo no mês, com nota. Quer testar com a primeira lavagem por minha conta? | Q39: A contatar
A40: 1 | B40: Lar de idosos | C40: Blumerville Casa de Repouso | E40: Rua Sol, 144 | F40: Gloria | G40: 3-6 km | J40: casaderepousoblumerville.com.br | K40: ilpi | L40: =SUBSTITUTE(SUBSTITUTE(SUBSTITUTE(SUBSTITUTE($H40,"(",""),")","")," ",""),"-","") | M40: =SUBSTITUTE(SUBSTITUTE(SUBSTITUTE(SUBSTITUTE($I40,"(",""),")","")," ",""),"-","") | N40: =IF(LEN($L40)=11,$L40,IF(LEN($M40)=11,$M40,"")) | O40: =IF($N40="","",HYPERLINK("https://wa.me/55"&$N40,"Abrir conversa")) | P40: =SUBSTITUTE(INDEX(Mensagens!$D$2:$D$12,MATCH($K40,Mensagens!$A$2:$A$12,0)),"[nome]",$C40) -> Bom dia, eu gostaria de falar com a administração, por favor. Somos a lavanderia do Posto Zandoná, na Ottokar Doerffel. Autosserviço com máquinas industriais, das 6h às 22h, e trabalhamos com conta faturada mensal e nota fiscal para instituições. A ideia é simples: em vez de manter máquina doméstica rodando o dia inteiro, a funcionária traz o enxoval duas ou três vezes por semana e resolve tudo de uma vez — inclusive cobertor e edredom, que é o que mais trava lavanderia interna no inverno. Posso passar os valores pra vocês compararem com o custo cheio de lavar internamente: energia, água, produto, manutenção da máquina e as horas da funcionária? | Q40: A contatar
...

Sheet Anfitriões Airbnb
A1: Preencha as colunas amarelas com o que você achar nos anúncios. O telefone NÃO aparece no Airbnb — veja a aba Como usar. A linha 3 é só um exemplo: apague antes de usar.
A2: Anúncio (título) | B2: Prédio | C2: Bairro | D2: Anfitrião | E2: Nº de anúncios do anfitrião | F2: Link do anúncio | G2: Telefone (quando achar) | H2: Onde achou o telefone | I2: Telefone (dígitos) | J2: Tipo | K2: Link WhatsApp | L2: Mensagem pronta | M2: Status
A3: Estúdio 08 | B3: a localizar (studios numerados 01 a 08) | C3: Anita Garibaldi | D3: Sergio | E3: 3 | F3: https://www.airbnb.com.br/rooms/... | G3: (47) 90000-0000 | H3: Instagram do prédio | I3: =SUBSTITUTE(SUBSTITUTE(SUBSTITUTE(SUBSTITUTE($G3,"(",""),")","")," ",""),"-","") -> 47900000000 | J3: =IF($I3="","",IF(LEN($I3)=11,"celular",IF(LEN($I3)=10,"fixo","conferir"))) -> celular | K3: =IF($J3="celular",HYPERLINK("https://wa.me/55"&$I3,"Abrir conversa"),"") -> Abrir conversa | L3: =IF($A3="","",SUBSTITUTE(INDEX(Mensagens!$D$2:$D$12,MATCH("anfitriao",Mensagens!$A$2:$A$12,0)),"[nome]",IF($D3="",$A3,$D3))) -> Oi, Sergio! Sou o Luis Carlos, da lavanderia do Posto Zandoná, na Ottokar Doerffel, 1489. Já tem anfitrião aqui do bairro usando a gente pra virar apartamento: traz o enxoval de todas as unidades de uma vez, usa duas ou três máquinas ao mesmo tempo, e em cerca de uma hora sai com tudo lavado e seco. É autosserviço, então você não depende de prazo de lavanderia nem de ninguém: entra, lava, seca e leva. Das 6h às 22h, estacionamento na porta — e dá pra abastecer ou lavar o carro na mesma parada. A primeira lavagem é por minha conta. Quer testar na próxima virada?
I4: =SUBSTITUTE(SUBSTITUTE(SUBSTITUTE(SUBSTITUTE($G4,"(",""),")","")," ",""),"-","") | J4: =IF($I4="","",IF(LEN($I4)=11,"celular",IF(LEN($I4)=10,"fixo","conferir"))) | K4: =IF($J4="celular",HYPERLINK("https://wa.me/55"&$I4,"Abrir conversa"),"") | L4: =IF($A4="","",SUBSTITUTE(INDEX(Mensagens!$D$2:$D$12,MATCH("anfitriao",Mensagens!$A$2:$A$12,0)),"[nome]",IF($D4="",$A4,$D4)))
I5: =SUBSTITUTE(SUBSTITUTE(SUBSTITUTE(SUBSTITUTE($G5,"(",""),")","")," ",""),"-","") | J5: =IF($I5="","",IF(LEN($I5)=11,"celular",IF(LEN($I5)=10,"fixo","conferir"))) | K5: =IF($J5="celular",HYPERLINK("https://wa.me/55"&$I5,"Abrir conversa"),"") | L5: =IF($A5="","",SUBSTITUTE(INDEX(Mensagens!$D$2:$D$12,MATCH("anfitriao",Mensagens!$A$2:$A$12,0)),"[nome]",IF($D5="",$A5,$D5)))
I6: =SUBSTITUTE(SUBSTITUTE(SUBSTITUTE(SUBSTITUTE($G6,"(",""),")","")," ",""),"-","") | J6: =IF($I6="","",IF(LEN($I6)=11,"celular",IF(LEN($I6)=10,"fixo","conferir"))) | K6: =IF($J6="celular",HYPERLINK("https://wa.me/55"&$I6,"Abrir conversa"),"") | L6: =IF($A6="","",SUBSTITUTE(INDEX(Mensagens!$D$2:$D$12,MATCH("anfitriao",Mensagens!$A$2:$A$12,0)),"[nome]",IF($D6="",$A6,$D6)))
I7: =SUBSTITUTE(SUBSTITUTE(SUBSTITUTE(SUBSTITUTE($G7,"(",""),")","")," ",""),"-","") | J7: =IF($I7="","",IF(LEN($I7)=11,"celular",IF(LEN($I7)=10,"fixo","conferir"))) | K7: =IF($J7="celular",HYPERLINK("https://wa.me/55"&$I7,"Abrir conversa"),"") | L7: =IF($A7="","",SUBSTITUTE(INDEX(Mensagens!$D$2:$D$12,MATCH("anfitriao",Mensagens!$A$2:$A$12,0)),"[nome]",IF($D7="",$A7,$D7)))
I8: =SUBSTITUTE(SUBSTITUTE(SUBSTITUTE(SUBSTITUTE($G8,"(",""),")","")," ",""),"-","") | J8: =IF($I8="","",IF(LEN($I8)=11,"celular",IF(LEN($I8)=10,"fixo","conferir"))) | K8: =IF($J8="celular",HYPERLINK("https://wa.me/55"&$I8,"Abrir conversa"),"") | L8: =IF($A8="","",SUBSTITUTE(INDEX(Mensagens!$D$2:$D$12,MATCH("anfitriao",Mensagens!$A$2:$A$12,0)),"[nome]",IF($D8="",$A8,$D8)))
I9: =SUBSTITUTE(SUBSTITUTE(SUBSTITUTE(SUBSTITUTE($G9,"(",""),")","")," ",""),"-","") | J9: =IF($I9="","",IF(LEN($I9)=11,"celular",IF(LEN($I9)=10,"fixo","conferir"))) | K9: =IF($J9="celular",HYPERLINK("https://wa.me/55"&$I9,"Abrir conversa"),"") | L9: =IF($A9="","",SUBSTITUTE(INDEX(Mensagens!$D$2:$D$12,MATCH("anfitriao",Mensagens!$A$2:$A$12,0)),"[nome]",IF($D9="",$A9,$D9)))
I10: =SUBSTITUTE(SUBSTITUTE(SUBSTITUTE(SUBSTITUTE($G10,"(",""),")","")," ",""),"-","") | J10: =IF($I10="","",IF(LEN($I10)=11,"celular",IF(LEN($I10)=10,"fixo","conferir"))) | K10: =IF($J10="celular",HYPERLINK("https://wa.me/55"&$I10,"Abrir conversa"),"") | L10: =IF($A10="","",SUBSTITUTE(INDEX(Mensagens!$D$2:$D$12,MATCH("anfitriao",Mensagens!$A$2:$A$12,0)),"[nome]",IF($D10="",$A10,$D10)))
I11: =SUBSTITUTE(SUBSTITUTE(SUBSTITUTE(SUBSTITUTE($G11,"(",""),")","")," ",""),"-","") | J11: =IF($I11="","",IF(LEN($I11)=11,"celular",IF(LEN($I11)=10,"fixo","conferir"))) | K11: =IF($J11="celular",HYPERLINK("https://wa.me/55"&$I11,"Abrir conversa"),"") | L11: =IF($A11="","",SUBSTITUTE(INDEX(Mensagens!$D$2:$D$12,MATCH("anfitriao",Mensagens!$A$2:$A$12,0)),"[nome]",IF($D11="",$A11,$D11)))
I12: =SUBSTITUTE(SUBSTITUTE(SUBSTITUTE(SUBSTITUTE($G12,"(",""),")","")," ",""),"-","") | J12: =IF($I12="","",IF(LEN($I12)=11,"celular",IF(LEN($I12)=10,"fixo","conferir"))) | K12: =IF($J12="celular",HYPERLINK("https://wa.me/55"&$I12,"Abrir conversa"),"") | L12: =IF($A12="","",SUBSTITUTE(INDEX(Mensagens!$D$2:$D$12,MATCH("anfitriao",Mensagens!$A$2:$A$12,0)),"[nome]",IF($D12="",$A12,$D12)))
I13: =SUBSTITUTE(SUBSTITUTE(SUBSTITUTE(SUBSTITUTE($G13,"(",""),")","")," ",""),"-","") | J13: =IF($I13="","",IF(LEN($I13)=11,"celular",IF(LEN($I13)=10,"fixo","conferir"))) | K13: =IF($J13="celular",HYPERLINK("https://wa.me/55"&$I13,"Abrir conversa"),"") | L13: =IF($A13="","",SUBSTITUTE(INDEX(Mensagens!$D$2:$D$12,MATCH("anfitriao",Mensagens!$A$2:$A$12,0)),"[nome]",IF($D13="",$A13,$D13)))
I14: =SUBSTITUTE(SUBSTITUTE(SUBSTITUTE(SUBSTITUTE($G14,"(",""),")","")," ",""),"-","") | J14: =IF($I14="","",IF(LEN($I14)=11,"celular",IF(LEN($I14)=10,"fixo","conferir"))) | K14: =IF($J14="celular",HYPERLINK("https://wa.me/55"&$I14,"Abrir conversa"),"") | L14: =IF($A14="","",SUBSTITUTE(INDEX(Mensagens!$D$2:$D$12,MATCH("anfitriao",Mensagens!$A$2:$A$12,0)),"[nome]",IF($D14="",$A14,$D14)))
I15: =SUBSTITUTE(SUBSTITUTE(SUBSTITUTE(SUBSTITUTE($G15,"(",""),")","")," ",""),"-","") | J15: =IF($I15="","",IF(LEN($I15)=11,"celular",IF(LEN($I15)=10,"fixo","conferir"))) | K15: =IF($J15="celular",HYPERLINK("https://wa.me/55"&$I15,"Abrir conversa"),"") | L15: =IF($A15="","",SUBSTITUTE(INDEX(Mensagens!$D$2:$D$12,MATCH("anfitriao",Mensagens!$A$2:$A$12,0)),"[nome]",IF($D15="",$A15,$D15)))
... I32: =SUBSTITUTE(SUBSTITUTE(SUBSTITUTE(SUBSTITUTE($G32,"(",""),")","")," ",""),"-","") | J32: =IF($I32="","",IF(LEN($I32)=11,"celular",IF(LEN($I32)=10,"fixo","conferir"))) | K32: =IF($J32="celular",HYPERLINK("https://wa.me/55"&$I32,"Abrir conversa"),"") | L32: =IF($A32="","",SUBSTITUTE(INDEX(Mensagens!$D$2:$D$12,MATCH("anfitriao",Mensagens!$A$2:$A$12,0)),"[nome]",IF($D32="",$A32,$D32)))

Sheet Mensagens
A1: chave | B1: tipo de cliente | C1: canal | D1: texto da mensagem
A2: pousada | B2: Pousada e hostel de até 10 quartos | C2: WhatsApp | D2: Bom dia, [nome]! Aqui é o Luis Carlos, da lavanderia do Posto Zandoná, na Ottokar Doerffel, 1489. É autosserviço — vocês mesmos usam as máquinas — mas são industriais: o enxoval de uma diária inteira vai de uma vez e sai seco na secadora em cerca de uma hora. Nada de lençol pendurado três dias no inverno. Abrimos das 6h às 22h, com estacionamento na porta. E para empresa eu faturo no mês, com nota. Queria te dar a primeira lavagem por conta da casa, pra vocês medirem quanto tempo economiza. Posso deixar o cupom aí?
A3: anfitriao | B3: Anfitrião de Airbnb / dono de 2 a 5 studios | C3: WhatsApp · use quando encontrar o anfitrião | D3: Oi, [nome]! Sou o Luis Carlos, da lavanderia do Posto Zandoná, na Ottokar Doerffel, 1489. Já tem anfitrião aqui do bairro usando a gente pra virar apartamento: traz o enxoval de todas as unidades de uma vez, usa duas ou três máquinas ao mesmo tempo, e em cerca de uma hora sai com tudo lavado e seco. É autosserviço, então você não depende de prazo de lavanderia nem de ninguém: entra, lava, seca e leva. Das 6h às 22h, estacionamento na porta — e dá pra abastecer ou lavar o carro na mesma parada. A primeira lavagem é por minha conta. Quer testar na próxima virada?
A4: zelador | B4: Zelador ou síndico de prédio de studios | C4: Presencial | D4: Bom dia! Sou o Luis Carlos, da lavanderia do Posto Zandoná, aqui na Ottokar Doerffel, 1489 — pertinho do prédio. É autosserviço com máquina industrial, das 6h às 22h. O que mais traz morador daqui é edredom, cobertor e tapete, que não entram na máquina de apartamento. Vi que o [nome] tem bastante studio alugado por temporada, e esse pessoal vira enxoval toda semana. Posso deixar cupons de primeira lavagem grátis na portaria pros moradores, e um cartaz pequeno no mural se o síndico autorizar?
A5: gestora | B5: Administradora e co-host de temporada | C5: WhatsApp | D5: Bom dia, [nome]. Sou o Luis Carlos, da lavanderia do Posto Zandoná (Ottokar Doerffel, 1489, Anita Garibaldi). Autosserviço com máquinas industriais: a equipe de limpeza de vocês resolve o enxoval de vários imóveis numa parada só — lava e seca em cerca de uma hora, das 6h às 22h, com estacionamento na porta. Pra quem administra carteira eu abro conta faturada: a equipe usa as máquinas o mês todo e vocês recebem uma nota só no fechamento, sem ninguém pagando do próprio bolso e pedindo reembolso depois. Topa testar com um imóvel? A primeira lavagem é por minha conta.
A6: construtora | B6: Construtora e incorporadora | C6: WhatsApp ou e-mail | D6: Bom dia. Sou o Luis Carlos, da lavanderia do Posto Zandoná, na Ottokar Doerffel, 1489 — a poucos minutos de vocês. Vocês entregam bastante unidade compacta de investidor, e quem coloca o imóvel pra temporada esbarra sempre no mesmo ponto: studio não tem área de serviço, e lençol de hóspede não seca dentro de apartamento. Queria propor que a gente entre no kit de entrega de chaves: cupom de primeira lavagem grátis pro comprador e condição fixa pros proprietários do empreendimento, sem custo nenhum pra construtora. Consigo 15 minutos com quem cuida do relacionamento com os compradores?
A7: bureau | B7: Convention & Visitors Bureau | C7: Ligação ou e-mail | D7: Bom dia. Sou o Luis Carlos, da lavanderia do Posto Zandoná, na Ottokar Doerffel, 1489 — somos quase vizinhos de vocês, no 1733. Somos autosserviço com máquinas industriais, das 6h às 22h, e atendemos pousada e hostel pequeno da região central. Queria entender como funciona a relação de vocês com os associados e se cabe uma condição para a rede — pensando no pico do Festival de Dança, quando pousada pequena estoura a capacidade de lavar e precisa de uma válvula de escape perto. Consigo uma conversa de 20 minutos esta semana?
A8: ilpi | B8: Lar de idosos e casa de repouso | C8: Ligação para a administração | D8: Bom dia, eu gostaria de falar com a administração, por favor. Somos a lavanderia do Posto Zandoná, na Ottokar Doerffel. Autosserviço com máquinas industriais, das 6h às 22h, e trabalhamos com conta faturada mensal e nota fiscal para instituições. A ideia é simples: em vez de manter máquina doméstica rodando o dia inteiro, a funcionária traz o enxoval duas ou três vezes por semana e resolve tudo de uma vez — inclusive cobertor e edredom, que é o que mais trava lavanderia interna no inverno. Posso passar os valores pra vocês compararem com o custo cheio de lavar internamente: energia, água, produto, manutenção da máquina e as horas da funcionária?
A9: pet | B9: Pet shop e banho e tosa | C9: Presencial | D9: Oi, tudo bem? Sou o Luis Carlos, da lavanderia aqui do Posto Zandoná, na Ottokar Doerffel — a poucos minutos daqui. Autosserviço, com máquina e secadora industrial. Pra banho e tosa o ganho é a secadora: a toalha sai seca na hora, não fica aquele monte pendurado esperando e azedando. Abrimos às 6h, dá pra resolver antes de abrir a loja, e tem estacionamento na porta. Primeira lavagem por minha conta — quer que eu deixe o cupom aqui?
A10: restaurante | B10: Restaurante | C10: Presencial, com o responsável | D10: Oi, posso falar com o responsável? Sou o Luis Carlos, da lavanderia do Posto Zandoná, na Ottokar Doerffel, 1489. Autosserviço com máquinas industriais, das 6h às 22h — pega antes de abrir e depois de fechar. Pano de copa, avental e toalha de mesa lavam e secam numa parada só. O que costuma resolver é não depender mais de alguém levar pra lavar em casa no fim de semana. E pra empresa eu faturo no mês, com nota. Quer testar com a primeira lavagem por minha conta?
A11: beleza | B11: Barbearia, salão e estética | C11: Presencial | D11: Oi, tudo bem? Sou o Luis Carlos, da lavanderia do Posto Zandoná, aqui na Ottokar Doerffel. Autosserviço com máquina e secadora industrial. Pra salão o ponto é a secadora: toalha que seca no varal fica dura e com cheiro de úmido; na secadora volta macia no mesmo dia. É uma parada de uma hora por semana, e ninguém da equipe precisa levar sacola pra casa. Deixo a primeira lavagem por minha conta pra você comparar. Pode ser?
A12: academia | B12: Academia e estúdio | C12: Presencial | D12: Oi! Sou o Luis Carlos, da lavanderia do Posto Zandoná, aqui na Ottokar Doerffel. Autosserviço com máquina e secadora industrial: toalha de treino e pano de higienização lavam e secam numa parada só — sem máquina rodando no intervalo e sem ninguém da recepção cuidando disso. Das 6h às 22h, com estacionamento na porta. Primeira lavagem por minha conta pra você ver o resultado. Quando fica bom testar?
